Workbook

Sheet source data
A1: Section | B1: printer | C1: AMS | D1: filament | E1: accessories | F1: material | G1: makers supply
A3: printer_brand | B3: Bambu Lab | C3: add new
A4: bambuLab_printerSeries | B4: A series | C4: add new
A5: bambuLab-aSeries_printerModel | B5: A1 mini | C5: add new
A7: AMS_brand | B7: Bambu Lab | C7: add new
A8: BambuLab_AMSmodel | B8: AMS lite | C8: add new
A10: filament_brand | B10: Bambu | C10: eSUN | D10: add new
A11: filament_family | B11: PLA | C11: PETG | D11: TPU | E11: add new
A12: Bambu-PLA_type | B12: PLA basic | C12: PLA matte | D12: add new
A13: Bambu-PLA-basic_colourName | B13: black | C13: add new
A14: Bambu-PLA-matte_colourName | B14: scarlet red | C14: add new
A15: eSUN-PLA_type | B15: standard | C15: PLA+ | D15: PLA+ HS | E15: matte | F15: Silk PLA | G15: Glow in the dark | H15: PLA-LW | I15: add new
A16: eSUN-PLA-standard_colourName | B16: clear | C16: add new
A17: eSUN-PLA-PLAplus_colourName | B17: warm white | C17: blue | D17: red | E17: add new
A18: eSUN-PLA-PLAplusHS_colourName | B18: black | C18: blue | D18: bone white | E18: brown | F18: dark blue | G18: fire engine red | H18: gold | I18: green | J18: grey | K18: light brown | L18: olive green | M18: orange | N18: peak green | O18: pine green | P18: pink | Q18: red | R18: silver | S18: skin / beige | T18: space blue | U18: very peri | V18: warm white | W18: yellow | X18: add new
A19: eSUN-PLA-matte_colourName | B19: milky white | C19: add new
A20: eSUN-PLA-silkPLA_type | B20: mystic triple colour | C20: add new
A21: eSUN-PLA-silkPLA-mysticTripleColour_colourName | B21: gold/red/green | C21: add new
A22: sSUN-PLA-glowInDark_colourName | B22: luminous green | C22: add new
A23: eSUN-PLA-PLALW_colourName | B23: white | C23: add new
A24: eSUN-PETG_type | B24: standard | C24: PETG+ HS | D24: add new
A25: eSUN-PETG-standard_colourName | B25: solid white | C25: add new
A26: eSUN-PETG-PETGplusHS_colourName | B26: solid green | C26: add new
A27: eSUN-TPU_type | B27: 95A | C27: add new
A28: eSUN-TPU-95A_colourName | B28: black | C28: add new
A29: filament_spoolType | B29: spool | C29: refill | D29: add new
A30: filament_spoolSize | B30: 300g | C30: 1kg | D30: add new
A31: filament_colourFamily | B31: black | C31: blue | D31: brown | E31: green | F31: grey | G31: orange | H31: pink | I31: purple | J31: red | K31: white | L31: yellow | M31: natural | N31: special | O31: add new
A32: filament_colourHEX
A33: filament_printerModelCompatibility | B33: A1 mini | C33: selection | D33: all
A34: filament_AMScompatibility | B34: AMS lite | C34: selection | D34: all | E34: none
A36: accessories_brand | B36: Bambu | C36: eSUN | D36: add new
A37: accessories_category | B37: build plate | C37: hotend | D37: upgrade | E37: spare parts | F37: filament accessories | G37: consumables | H37: cutting | I37: laser | J37: add new
A38: accessories_printerModelCompatibility | B38: A1 mini | C38: selection | D38: all
A39: buildPlate-A1mini_type | B39: Smooth PEI Plate | C39: Dual-Texture PEI Plate | D39: Cool Plate SuperTack | E39: add new
A40: hotend-A1mini_type | B40: stainless steel | C40: hardened steel | D40: add new
A41: hotend-A1mini-stainlessSteel_size | B41: 0.2mm | C41: 0.4mm | D41: add new
A42: hotend-A1mini-hardenedSteel_size | B42: 0.4mm | C42: 0.6mm | D42: 0.8mm | E42: add new
A43: upgrade_type
A44: spareParts_type | B44: Screws Kit - A1 Series and AMS lite | C44: Hotend Heating Assembly - A1 Series | D44: Heatbed Nozzle Wiper - A1 mini | E44: Purge Wiper - A1 Series | F44: Replacement Filament Cutter | G44: Bambu Scraper 3 pcs | H44: PTFE Tubes | I44: Hotend Silicone Sock - A1 Series | J44: add new
...

Sheet inventory_printer
A1: inventory_id | B1: ='source data'!A3 -> printer_brand | C1: ='source data'!A4 -> bambuLab_printerSeries | D1: ='source data'!A5 -> bambuLab-aSeries_printerModel
A2: 1 | B2: Bambu Lab | C2: A series | D2: A1 mini

Sheet inventory_AMS
A1: inventory_id | B1: ='source data'!A7 -> AMS_brand | C1: ='source data'!A8 -> BambuLab_AMSmodel
A2: 50 | B2: Bambu Lab | C2: AMS lite

Sheet inventory_filament
A1: inventory_id | B1: ='source data'!A10 -> filament_brand | C1: ='source data'!A11 -> filament_family | D1: ='source data'!A12 -> Bambu-PLA_type | E1: ='source data'!A13 -> Bambu-PLA-basic_colourName | F1: ='source data'!A14 -> Bambu-PLA-matte_colourName | G1: ='source data'!A15 -> eSUN-PLA_type | H1: ='source data'!A16 -> eSUN-PLA-standard_colourName | I1: ='source data'!A17 -> eSUN-PLA-PLAplus_colourName | J1: ='source data'!A18 -> eSUN-PLA-PLAplusHS_colourName | K1: ='source data'!A19 -> eSUN-PLA-matte_colourName | L1: ='source data'!A20 -> eSUN-PLA-silkPLA_type | M1: ='source data'!A21 -> eSUN-PLA-silkPLA-mysticTripleColour_colourName | N1: ='source data'!A22 -> sSUN-PLA-glowInDark_colourName | O1: ='source data'!A23 -> eSUN-PLA-PLALW_colourName | P1: ='source data'!A24 -> eSUN-PETG_type | Q1: ='source data'!A25 -> eSUN-PETG-standard_colourName | R1: ='source data'!A26 -> eSUN-PETG-PETGplusHS_colourName | S1: ='source data'!A27 -> eSUN-TPU_type | T1: ='source data'!A28 -> eSUN-TPU-95A_colourName | U1: ='source data'!A29 -> filament_spoolType | V1: ='source data'!A30 -> filament_spoolSize | W1: ='source data'!A31 -> filament_colourFamily | X1: ='source data'!A32 -> filament_colourHEX | Y1: ='source data'!A33 -> filament_printerModelCompatibility | Z1: ='source data'!A34 -> filament_AMScompatibility
A2: 100 | B2: Bambu | C2: PLA | D2: PLA basic | E2: black | U2: spool | V2: 1kg | W2: black
A3: 101 | B3: Bambu | C3: PLA | D3: PLA matte | F3: scarlet red | U3: spool | V3: 1kg | W3: red
A4: 102 | B4: eSUN | C4: PLA | G4: PLA+ | I4: warm white | U4: spool | V4: 1kg | W4: white
A5: 103 | B5: eSUN | C5: PETG | P5: standard | Q5: solid white | U5: refill | V5: 1kg | W5: white
A6: 104 | B6: eSUN | C6: PLA | G6: Glow in the dark | N6: luminous green | U6: spool | V6: 1kg | W6: special
A7: 105 | B7: eSUN | C7: PLA | G7: matte | K7: milky white | U7: spool | V7: 1kg | W7: white
A8: 106 | B8: eSUN | C8: PLA | G8: PLA+ HS | J8: black | U8: spool | V8: 1kg | W8: black
A9: 107 | B9: eSUN | C9: PLA | G9: PLA+ HS | J9: blue | U9: spool | V9: 1kg | W9: blue
A10: 108 | B10: eSUN | C10: PLA | G10: PLA+ | I10: blue | U10: refill | V10: 1kg | W10: blue
A11: 109 | B11: eSUN | C11: PLA | G11: PLA+ HS | J11: bone white | U11: spool | V11: 1kg | W11: natural
A12: 110 | B12: eSUN | C12: PLA | G12: PLA+ HS | J12: brown | U12: spool | V12: 1kg | W12: brown
A13: 111 | B13: eSUN | C13: PLA | G13: PLA+ HS | J13: dark blue | U13: spool | V13: 1kg | W13: blue
A14: 112 | B14: eSUN | C14: PLA | G14: PLA+ HS | J14: gold | U14: spool | V14: 1kg | W14: yellow
A15: 113 | B15: eSUN | C15: PLA | G15: PLA+ HS | J15: green | U15: spool | V15: 1kg | W15: green
A16: 114 | B16: eSUN | C16: PLA | G16: PLA+ HS | J16: grey | U16: spool | V16: 1kg | W16: grey
A17: 115 | B17: eSUN | C17: PLA | G17: PLA+ HS | J17: light brown | U17: spool | V17: 1kg | W17: brown
A18: 116 | B18: eSUN | C18: PLA | G18: PLA+ HS | J18: olive green | U18: spool | V18: 1kg | W18: green
A19: 117 | B19: eSUN | C19: PLA | G19: PLA+ HS | J19: orange | U19: spool | V19: 1kg | W19: orange
A20: 118 | B20: eSUN | C20: PLA | G20: PLA+ HS | J20: peak green | U20: spool | V20: 1kg | W20: green
A21: 119 | B21: eSUN | C21: PLA | G21: PLA+ HS | J21: pine green | U21: spool | V21: 1kg | W21: green
A22: 120 | B22: eSUN | C22: PLA | G22: PLA+ HS | J22: pink | U22: spool | V22: 1kg | W22: pink
A23: 121 | B23: eSUN | C23: PLA | G23: PLA+ HS | J23: red | U23: spool | V23: 1kg | W23: red
A24: 122 | B24: eSUN | C24: PLA | G24: PLA+ | I24: red | U24: refill | V24: 1kg | W24: red
A25: 123 | B25: eSUN | C25: PLA | G25: PLA+ HS | J25: fire engine red | U25: spool | V25: 1kg | W25: red
A26: 124 | B26: eSUN | C26: PLA | G26: PLA+ HS | J26: silver | U26: spool | V26: 1kg | W26: grey
A27: 125 | B27: eSUN | C27: PLA | G27: PLA+ HS | J27: skin / beige | U27: spool | V27: 1kg | W27: natural
A28: 126 | B28: eSUN | C28: PLA | G28: PLA+ HS | J28: space blue | U28: spool | V28: 1kg | W28: blue
A29: 127 | B29: eSUN | C29: PLA | G29: PLA+ HS | J29: very peri | U29: spool | V29: 1kg | W29: purple
A30: 128 | B30: eSUN | C30: PLA | G30: PLA+ HS | J30: warm white | U30: spool | V30: 1kg | W30: white
A31: 129 | B31: eSUN | C31: PLA | G31: PLA+ | I31: warm white | U31: refill | V31: 1kg | W31: white
A32: 130 | B32: eSUN | C32: PLA | G32: PLA+ HS | J32: yellow | U32: spool | V32: 1kg | W32: yellow
A33: 131 | B33: eSUN | C33: PLA | G33: standard | H33: clear | U33: spool | V33: 1kg | W33: special
A34: 132 | B34: eSUN | C34: PLA | G34: Silk PLA | L34: mystic triple colour | M34: gold/red/green | U34: spool | V34: 1kg | W34: special
A35: 133 | B35: eSUN | C35: TPU | S35: 95A | T35: black | U35: spool | V35: 1kg | W35: black
A36: 134 | B36: eSUN | C36: PLA | G36: PLA-LW | O36: white | U36: spool | V36: 1kg | W36: white
A37: 135 | B37: eSUN | C37: PETG | P37: PETG+ HS | Q37: solid green | U37: spool | V37: 1kg | W37: green

Sheet inventory_accessories
A1: inventory_id | B1: ='source data'!A36 -> accessories_brand | C1: ='source data'!A37 -> accessories_category | D1: ='source data'!A38 -> accessories_printerModelCompatibility | E1: ='source data'!A39 -> buildPlate-A1mini_type | F1: ='source data'!A40 -> hotend-A1mini_type | G1: ='source data'!A41 -> hotend-A1mini-stainlessSteel_size | H1: ='source data'!A42 -> hotend-A1mini-hardenedSteel_size | I1: ='source data'!A43 -> upgrade_type | J1: ='source data'!A44 -> spareParts_type | K1: ='source data'!A45 -> screwsKit_type | L1: ='source data'!A46 -> screwsKit-machineScrew_type | M1: ='source data'!A47 -> screwsKit-selfTappingScrew_type | N1: ='source data'!A48 -> screwsKit-washer_type | O1: ='source data'!A49 -> screwsKit-spring_type | P1: ='source data'!A50 -> filamentAccessories_type | Q1: ='source data'!A51 -> filamentAccessories-filamentDryer_model | R1: ='source data'!A52 -> filamentAccessories-filamentSpool_model | S1: ='source data'!A53 -> filamentAccessories-vacuumBags_model | T1: ='source data'!A54 -> filamentAccessories-vacuumPump_model | U1: ='source data'!A55 -> consumables_type
A2: 1000 | B2: Bambu | C2: hotend | F2: stainless steel | G2: 0.2mm
A3: 1001 | B3: Bambu | C3: build plate | E3: Smooth PEI Plate
A4: 1002 | B4: Bambu | C4: hotend | F4: hardened steel | H4: 0.4mm
A5: 1003 | B5: Bambu | C5: consumables | U5: liquid glue
A6: 1004 | B6: eSUN | C6: filament accessories | P6: filament dryer | Q6: eBox Lite
A7: 1005 | B7: eSUN | C7: filament accessories | P7: filament spool | R7: eSpool+ Polycarbonate
A8: 1006 | B8: eSUN | C8: filament accessories | P8: vacuum bags | S8: 15Pcs Vacuum Bag
A9: 1007 | B9: eSUN | C9: filament accessories | P9: vacuum pump | T9: ePump
A10: 1008 | B10: Bambu | C10: hotend | F10: hardened steel | H10: 0.8mm
A11: 1009 | B11: Bambu | C11: hotend | F11: hardened steel | H11: 0.6mm
A12: 1010 | B12: Bambu | C12: build plate | E12: Dual-Texture PEI Plate
A13: 1011 | B13: Bambu | C13: build plate | E13: Cool Plate SuperTack
A14: 1012 | B14: Bambu | C14: spare parts | J14: Screws Kit - A1 Series and AMS lite | K14: machine screw | L14: M2x2.5 FHCS
A15: 1013 | B15: Bambu | C15: spare parts | J15: Screws Kit - A1 Series and AMS lite | K15: machine screw | L15: M2.5x5 FHCS
A16: 1014 | B16: Bambu | C16: spare parts | J16: Screws Kit - A1 Series and AMS lite | K16: self tapping screw | M16: BT2x5 SHCS
A17: 1015 | B17: Bambu | C17: spare parts | J17: Screws Kit - A1 Series and AMS lite | K17: self tapping screw | M17: BT2.6x5 SHCS
A18: 1016 | B18: Bambu | C18: spare parts | J18: Screws Kit - A1 Series and AMS lite | K18: self tapping screw | M18: BT2.3x7 SHCS
A19: 1017 | B19: Bambu | C19: spare parts | J19: Screws Kit - A1 Series and AMS lite | K19: self tapping screw | M19: BT2x8 SHCS
A20: 1018 | B20: Bambu | C20: spare parts | J20: Screws Kit - A1 Series and AMS lite | K20: self tapping screw | M20: BT2.6x14 SHCS
A21: 1019 | B21: Bambu | C21: spare parts | J21: Screws Kit - A1 Series and AMS lite | K21: washer | N21: Stainless Steel Flat Washer
A22: 1020 | B22: Bambu | C22: spare parts | J22: Screws Kit - A1 Series and AMS lite | K22: self tapping screw | M22: BT2.6x8 SHCS
A23: 1021 | B23: Bambu | C23: spare parts | J23: Screws Kit - A1 Series and AMS lite | K23: self tapping screw | M23: BT3x8 SHCS
A24: 1022 | B24: Bambu | C24: spare parts | J24: Screws Kit - A1 Series and AMS lite | K24: self tapping screw | M24: BT3x12 SHCS
A25: 1023 | B25: Bambu | C25: spare parts | J25: Screws Kit - A1 Series and AMS lite | K25: machine screw | L25: M3x12 FHCS
A26: 1024 | B26: Bambu | C26: spare parts | J26: Screws Kit - A1 Series and AMS lite | K26: self tapping screw | M26: BT2x13 SHCS
A27: 1025 | B27: Bambu | C27: spare parts | J27: Screws Kit - A1 Series and AMS lite | K27: spring | O27: 0.9x11 mm Helical Compression Spring
A28: 1026 | B28: Bambu | C28: spare parts | J28: PTFE Tubes
A29: 1027 | B29: Bambu | C29: spare parts | J29: Hotend Silicone Sock - A1 Series
A30: 1028 | B30: Bambu | C30: spare parts | J30: Heatbed Nozzle Wiper - A1 mini
A31: 1029 | B31: Bambu | C31: spare parts | J31: Bambu Scraper 3 pcs
A32: 1030 | B32: Bambu | C32: spare parts | J32: Purge Wiper - A1 Series
A33: 1031 | B33: Bambu | C33: spare parts | J33: Replacement Filament Cutter
A34: 1032 | B34: Bambu | C34: consumables | U34: lubricant oil
A35: 1033 | B35: Bambu | C35: consumables | U35: lubricant grease

Sheet inventory_material
A1: inventory_id | B1: ='source data'!A58 -> material_brand | C1: ='source data'!A59 -> material_type
A2: 2000
A3: 2001
A4: 2002
A5: 2003
A6: 2004
A7: 2005
A8: 2006

Sheet inventroy_makers supply
A1: inventory_id | B1: ='source data'!A62 -> makersSupply_brand | C1: ='source data'!A63 -> makersSupply_type | D1: ='source data'!A64 -> hardware_type | E1: ='source data'!A65 -> fastener_type | F1: ='source data'!A66 -> spring_type | G1: ='source data'!A67 -> magnet_type
A2: 3000 | B2: Bambu | C2: hardware | D2: magnet | G2: D6x2 mm Round Magnet (20PCS) - CA004
A3: 3001 | B3: Bambu | C3: hardware | D3: fastener | E3: M2x4 BHCS Machine Screw AA162
A4: 3002 | B4: Bambu | C4: hardware | D4: fastener | E4: M3x10 FHCS Machine Screw AA188
A5: 3003 | B5: Bambu | C5: hardware | D5: spring | F5: Extension Springs 0.4x3x10 mm BA001

Sheet purchases
A1: inventory_id | B1: ='source data'!A70 -> purchase_date | C1: ='source data'!A71 -> purchase_orderNumber | D1: ='source data'!A72 -> purchase_store | E1: purchase_qty
A2: =inventory_printer!A2 -> 1 | B2: 45539 | C2: AU317201965 | D2: Bambu Lab | E2: 1
A3: =inventory_filament!A2 -> 100 | B3: 45539 | C3: AU317201965 | D3: Bambu Lab | E3: 1
A4: =inventory_filament!A3 -> 101 | B4: 45539 | C4: AU317201965 | D4: Bambu Lab | E4: 1
A5: =inventory_accessories!A2 -> 1000 | B5: 45556 | C5: AU513926369539567617 | D5: Bambu Lab | E5: 1
A6: =inventory_filament!A4 -> 102 | B6: 45578 | C6: 249-0278704-5258267 | D6: Amazon | E6: 2
A7: =inventory_filament!A6 -> 104 | B7: 45578 | C7: #80187SP | D7: Cubic Technology | E7: 1
A8: =inventory_filament!A7 -> 105 | B8: 45578 | C8: #80187SP | D8: Cubic Technology | E8: 1
A9: =inventory_filament!A8 -> 106 | B9: 45578 | C9: #80187SP | D9: Cubic Technology | E9: 1
A10: =inventory_filament!A9 -> 107 | B10: 45578 | C10: #80187SP | D10: Cubic Technology | E10: 1
A11: =inventory_filament!A21 -> 119 | B11: 45578 | C11: #80187SP | D11: Cubic Technology | E11: 1
A12: =inventory_filament!A28 -> 126 | B12: 45578 | C12: #80187SP | D12: Cubic Technology | E12: 1
A13: =inventory_filament!A34 -> 132 | B13: 45578 | C13: #80187SP | D13: Cubic Technology | E13: 1
A14: =inventory_filament!A16 -> 114 | B14: 45596 | C14: #81076SP | D14: Cubic Technology | E14: 1
A15: =inventory_filament!A20 -> 118 | B15: 45596 | C15: #81076SP | D15: Cubic Technology | E15: 1
A16: =inventory_filament!A14 -> 112 | B16: 45596 | C16: #81076SP | D16: Cubic Technology | E16: 1
A17: =inventory_filament!A26 -> 124 | B17: 45596 | C17: #81076SP | D17: Cubic Technology | E17: 1
A18: =inventory_filament!A10 -> 108 | B18: 45596 | C18: #81076SP | D18: Cubic Technology | E18: 1
A19: =inventory_filament!A31 -> 129 | B19: 45596 | C19: #81076SP | D19: Cubic Technology | E19: 1
A20: =inventory_filament!A24 -> 122 | B20: 45596 | C20: #81076SP | D20: Cubic Technology | E20: 1
A21: =inventory_accessories!A8 -> 1006 | B21: 45596 | C21: AE8194931660002354 | D21: Ali Express | E21: 1
A22: =inventory_AMS!A2 -> 50 | B22: 45597 | C22: AU528709429901545473 | D22: Bambu Lab | E22: 1
A23: =inventory_filament!A5 -> 103 | B23: 45597 | C23: #81094SP | D23: Cubic Technology | E23: 1
A24: =inventory_filament!A33 -> 131 | B24: 45597 | C24: #81094SP | D24: Cubic Technology | E24: 1
A25: =inventory_filament!A35 -> 133 | B25: 45597 | C25: #81094SP | D25: Cubic Technology | E25: 1
A26: =inventory_accessories!A3 -> 1001 | B26: 45597 | C26: AU528709429901545473 | D26: Bambu Lab | E26: 1
A27: =inventory_accessories!A4 -> 1002 | B27: 45597 | C27: AU528709429901545473 | D27: Bambu Lab | E27: 1
A28: =inventory_accessories!A5 -> 1003 | B28: 45597 | C28: AU528709429901545473 | D28: Bambu Lab | E28: 1
A29: =inventory_accessories!A6 -> 1004 | B29: 45597 | C29: #81094SP | D29: Cubic Technology | E29: 1
A30: =inventory_accessories!A7 -> 1005 | B30: 45597 | C30: #81094SP | D30: Cubic Technology | E30: 1
A31: =inventory_accessories!A10 -> 1008 | B31: 45598 | C31: AU528997370155401217 | D31: Bambu Lab | E31: 1
A32: =inventory_accessories!A11 -> 1009 | B32: 45598 | C32: AU528997370155401217 | D32: Bambu Lab | E32: 1
A33: =inventory_accessories!A12 -> 1010 | B33: 45598 | C33: AU528997370155401217 | D33: Bambu Lab | E33: 1
A34: =inventory_accessories!A14 -> 1012 | B34: 45598 | C34: AU528997370155401217 | D34: Bambu Lab | E34: 10
A35: =inventory_accessories!A15 -> 1013 | B35: 45598 | C35: AU528997370155401217 | D35: Bambu Lab | E35: 10
A36: =inventory_accessories!A16 -> 1014 | B36: 45598 | C36: AU528997370155401217 | D36: Bambu Lab | E36: 20
A37: =inventory_accessories!A17 -> 1015 | B37: 45598 | C37: AU528997370155401217 | D37: Bambu Lab | E37: 10
A38: =inventory_accessories!A18 -> 1016 | B38: 45598 | C38: AU528997370155401217 | D38: Bambu Lab | E38: 20
A39: =inventory_accessories!A19 -> 1017 | B39: 45598 | C39: AU528997370155401217 | D39: Bambu Lab | E39: 10
A40: =inventory_accessories!A20 -> 1018 | B40: 45598 | C40: AU528997370155401217 | D40: Bambu Lab | E40: 5
...
